<?xml version="1.0" ?>
<!-- =================================================================================== -->
<!-- |    This document was autogenerated by xacro from front_left_leg.urdf.xacro      | -->
<!-- |    EDITING THIS FILE BY HAND IS NOT RECOMMENDED                                 | -->
<!-- =================================================================================== -->
<robot name="ester">
  <!-- Dummy shoulder joint -->
  <link name="front_left_hip_aa_link"/>
  <link name="front_left_hip_fe_link">
    <inertial>
      <mass value="0.139328"/>
      <origin rpy="0 0 3.141592653589793" xyz="0.01808 0.004477 -0.014405"/>
      <inertia ixx="6.080E-05" ixy="-3.521E-06" ixz="2.540E-06" iyy="1.052E-04" iyz="1.247E-05" izz="7.157E-05"/>
    </inertial>
    <visual>
      <origin rpy="0 0 3.141592653589793" xyz="0 0 -0.003"/>
      <geometry>
        <mesh filename="package://ester_description/meshes/leg/front_hip_fe.stl" scale="0.001 0.001 0.001"/>
      </geometry>
    </visual>
    <collision>
      <origin rpy="0 0 3.141592653589793" xyz="0 0 -0.003"/>
      <geometry>
        <mesh filename="package://ester_description/meshes/leg/front_hip_fe.stl" scale="0.001 0.001 0.001"/>
      </geometry>
    </collision>
  </link>
  <joint name="front_left_hip_fe_joint" type="revolute">
    <origin rpy="0 0 0" xyz="0.083972 0.0878 0"/>
    <axis xyz="1 0 0"/>
    <limit effort="2.43" lower="-0.17453292519943295" upper="0.7853981633974483" velocity="83.33333333333333"/>
    <dynamics damping="0.05" friction="0.1"/>
    <parent link="front_left_hip_aa_link"/>
    <child link="front_left_hip_fe_link"/>
  </joint>
  <transmission name="front_left_hip_fe_transmission">
    <type>transmission_interface/SimpleTransmission</type>
    <joint name="front_left_hip_fe_joint">
      <hardwareInterface>hardware_interface/EffortJointInterface</hardwareInterface>
    </joint>
    <actuator name="front_left_hip_fe_motor">
      <hardwareInterface>hardware_interface/EffortJointInterface</hardwareInterface>
      <mechanicalReduction>1</mechanicalReduction>
    </actuator>
  </transmission>
  <link name="front_left_upper_leg_link">
    <inertial>
      <mass value="0.158127"/>
      <origin rpy="0 0 1.5707963267948966" xyz="0.0 0.022563 -0.07012"/>
      <inertia ixx="2.824E-04" ixy="4.259E-09" ixz="-6.584E-08" iyy="2.882E-04" iyz="3.543E-05" izz="3.742E-05"/>
    </inertial>
    <visual>
      <origin rpy="0 0 1.5707963267948966" xyz="0 0 0"/>
      <geometry>
        <mesh filename="package://ester_description/meshes/leg/front_upper_leg.stl" scale="0.001 0.001 0.001"/>
      </geometry>
    </visual>
    <collision>
      <origin rpy="0 0 1.5707963267948966" xyz="0 0 0"/>
      <geometry>
        <mesh filename="package://ester_description/meshes/leg/front_upper_leg.stl" scale="0.001 0.001 0.001"/>
      </geometry>
    </collision>
  </link>
  <joint name="front_left_upper_leg_joint" type="revolute">
    <origin rpy="0 0.7853981633974483 0" xyz="0 0.01415 0"/>
    <axis xyz="0 1 0"/>
    <limit effort="4.32" lower="-2.356194490192345" upper="2.356194490192345" velocity="46.875"/>
    <dynamics damping="0.05" friction="0.1"/>
    <parent link="front_left_hip_fe_link"/>
    <child link="front_left_upper_leg_link"/>
  </joint>
  <transmission name="front_left_upper_leg_transmission">
    <type>transmission_interface/SimpleTransmission</type>
    <joint name="front_left_upper_leg_joint">
      <hardwareInterface>hardware_interface/EffortJointInterface</hardwareInterface>
    </joint>
    <actuator name="front_left_upper_leg_motor">
      <hardwareInterface>hardware_interface/EffortJointInterface</hardwareInterface>
      <mechanicalReduction>1</mechanicalReduction>
    </actuator>
  </transmission>
  <link name="front_left_lower_leg_link">
    <inertial>
      <mass value="0.023961"/>
      <origin xyz="0 0.00816 -0.044589"/>
      <inertia ixx="3.727E-05" ixy="-5.628E-16" ixz="2.285E-15" iyy="3.709E-05" iyz="-5.027E-06" izz="1.815E-06"/>
    </inertial>
    <visual>
      <origin rpy="0 0 0" xyz="0 0 0"/>
      <geometry>
        <mesh filename="package://ester_description/meshes/leg/front_lower_leg.stl" scale="0.001 0.001 0.001"/>
      </geometry>
    </visual>
    <collision>
      <origin rpy="0 0 0" xyz="0 0 0"/>
      <geometry>
        <mesh filename="package://ester_description/meshes/leg/front_lower_leg.stl" scale="0.001 0.001 0.001"/>
      </geometry>
    </collision>
  </link>
  <joint name="front_left_lower_leg_joint" type="revolute">
    <axis xyz="0 1 0"/>
    <limit effort="4.32" lower="-2.5132741228718345" upper="2.5132741228718345" velocity="46.875"/>
    <dynamics damping="0.05" friction="0.1"/>
    <origin rpy="0 0 0" xyz="0 0.0315 -0.1232"/>
    <parent link="front_left_upper_leg_link"/>
    <child link="front_left_lower_leg_link"/>
  </joint>
  <transmission name="front_left_lower_leg_transmission">
    <type>transmission_interface/SimpleTransmission</type>
    <joint name="front_left_lower_leg_joint">
      <hardwareInterface>hardware_interface/EffortJointInterface</hardwareInterface>
    </joint>
    <actuator name="front_left_lower_leg_motor">
      <hardwareInterface>hardware_interface/EffortJointInterface</hardwareInterface>
      <mechanicalReduction>1</mechanicalReduction>
    </actuator>
  </transmission>
  <link name="front_left_foot_contact_link">
    <inertial>
      <mass value="0.01"/>
      <origin xyz="0 0 0"/>
      <inertia ixx="1e-9" ixy="0.0" ixz="0.0" iyy="1e-9" iyz="0.0" izz="1e-9"/>
    </inertial>
    <visual>
      <origin xyz="0 0 0"/>
      <geometry>
        <sphere radius="0.015"/>
      </geometry>
    </visual>
    <collision>
      <origin xyz="0 0 0"/>
      <geometry>
        <sphere radius="0.015"/>
      </geometry>
    </collision>
  </link>
  <joint name="front_left_foot_contact_joint" type="fixed">
    <origin xyz="0 0 -0.105"/>
    <parent link="front_left_lower_leg_link"/>
    <child link="front_left_foot_contact_link"/>
  </joint>
</robot>

