<?xml version="1.0" ?>
<!-- =================================================================================== -->
<!-- |    This document was autogenerated by xacro from rear_right_leg.urdf.xacro      | -->
<!-- |    EDITING THIS FILE BY HAND IS NOT RECOMMENDED                                 | -->
<!-- =================================================================================== -->
<robot name="ester">
  <!-- Dummy shoulder joint -->
  <link name="rear_right_hip_aa_link"/>
  <link name="rear_right_hip_fe_link">
    <inertial>
      <mass value="0.138767"/>
      <origin rpy="0 0 0" xyz="0.01668 0.004473 -0.014463"/>
      <inertia ixx="6.067E-05" ixy="-4.443E-06" ixz="3.065E-06" iyy="1.026E-04" iyz="1.247E-05" izz="6.917E-05"/>
    </inertial>
    <visual>
      <origin rpy="0 0 0" xyz="0 0 -0.003"/>
      <geometry>
        <mesh filename="package://ester_description/meshes/leg/rear_hip_fe.stl" scale="0.001 0.001 0.001"/>
      </geometry>
    </visual>
    <collision>
      <origin rpy="0 0 0" xyz="0 0 -0.003"/>
      <geometry>
        <mesh filename="package://ester_description/meshes/leg/rear_hip_fe.stl" scale="0.001 0.001 0.001"/>
      </geometry>
    </collision>
  </link>
  <joint name="rear_right_hip_fe_joint" type="revolute">
    <origin rpy="0 0 0" xyz="0.054678 -0.0878 0"/>
    <axis xyz="1 0 0"/>
    <limit effort="2.43" lower="-0.7853981633974483" upper="0.17453292519943295" velocity="83.33333333333333"/>
    <dynamics damping="0.05" friction="0.1"/>
    <parent link="rear_right_hip_aa_link"/>
    <child link="rear_right_hip_fe_link"/>
  </joint>
  <transmission name="rear_right_hip_fe_transmission">
    <type>transmission_interface/SimpleTransmission</type>
    <joint name="rear_right_hip_fe_joint">
      <hardwareInterface>hardware_interface/EffortJointInterface</hardwareInterface>
    </joint>
    <actuator name="rear_right_hip_fe_motor">
      <hardwareInterface>hardware_interface/EffortJointInterface</hardwareInterface>
      <mechanicalReduction>1</mechanicalReduction>
    </actuator>
  </transmission>
  <link name="rear_right_upper_leg_link">
    <inertial>
      <mass value="0.160653"/>
      <origin rpy="0 0 -1.5707963267948966" xyz="0.0 -0.02256 -0.07763"/>
      <inertia ixx="3.140E-04" ixy="6.009E-09" ixz="-7.395E-08" iyy="3.203E-04" iyz="3.738E-05" izz="3.808E-05"/>
    </inertial>
    <visual>
      <origin rpy="0 0 -1.5707963267948966" xyz="0 0 0"/>
      <geometry>
        <mesh filename="package://ester_description/meshes/leg/rear_upper_leg.stl" scale="0.001 0.001 0.001"/>
      </geometry>
    </visual>
    <collision>
      <origin rpy="0 0 -1.5707963267948966" xyz="0 0 0"/>
      <geometry>
        <mesh filename="package://ester_description/meshes/leg/rear_upper_leg.stl" scale="0.001 0.001 0.001"/>
      </geometry>
    </collision>
  </link>
  <joint name="rear_right_upper_leg_joint" type="revolute">
    <origin rpy="0 0 0" xyz="0 -0.01415 0"/>
    <axis xyz="0 1 0"/>
    <limit effort="4.32" lower="-2.356194490192345" upper="2.356194490192345" velocity="46.875"/>
    <dynamics damping="0.05" friction="0.1"/>
    <parent link="rear_right_hip_fe_link"/>
    <child link="rear_right_upper_leg_link"/>
  </joint>
  <transmission name="rear_right_upper_leg_transmission">
    <type>transmission_interface/SimpleTransmission</type>
    <joint name="rear_right_upper_leg_joint">
      <hardwareInterface>hardware_interface/EffortJointInterface</hardwareInterface>
    </joint>
    <actuator name="rear_right_upper_leg_motor">
      <hardwareInterface>hardware_interface/EffortJointInterface</hardwareInterface>
      <mechanicalReduction>1</mechanicalReduction>
    </actuator>
  </transmission>
  <link name="rear_right_lower_leg_link">
    <inertial>
      <mass value="0.029071"/>
      <origin xyz="0 -0.008801 -0.056722"/>
      <inertia ixx="6.791E-05" ixy="-1.480E-16" ixz="2.960E-15" iyy="6.774E-05" iyz="7.319E-06" izz="2.092E-06"/>
    </inertial>
    <visual>
      <origin rpy="0 0 3.141592653589793" xyz="0 0 0"/>
      <geometry>
        <mesh filename="package://ester_description/meshes/leg/rear_lower_leg.stl" scale="0.001 0.001 0.001"/>
      </geometry>
    </visual>
    <collision>
      <origin rpy="0 0 3.141592653589793" xyz="0 0 0"/>
      <geometry>
        <mesh filename="package://ester_description/meshes/leg/rear_lower_leg.stl" scale="0.001 0.001 0.001"/>
      </geometry>
    </collision>
  </link>
  <joint name="rear_right_lower_leg_joint" type="revolute">
    <axis xyz="0 1 0"/>
    <limit effort="4.32" lower="-2.5132741228718345" upper="2.5132741228718345" velocity="46.875"/>
    <dynamics damping="0.05" friction="0.1"/>
    <origin rpy="0 0 0" xyz="0 -0.0315 -0.134"/>
    <parent link="rear_right_upper_leg_link"/>
    <child link="rear_right_lower_leg_link"/>
  </joint>
  <transmission name="rear_right_lower_leg_transmission">
    <type>transmission_interface/SimpleTransmission</type>
    <joint name="rear_right_lower_leg_joint">
      <hardwareInterface>hardware_interface/EffortJointInterface</hardwareInterface>
    </joint>
    <actuator name="rear_right_lower_leg_motor">
      <hardwareInterface>hardware_interface/EffortJointInterface</hardwareInterface>
      <mechanicalReduction>1</mechanicalReduction>
    </actuator>
  </transmission>
  <link name="rear_right_foot_contact_link">
    <inertial>
      <mass value="0.01"/>
      <origin xyz="0 0 0"/>
      <inertia ixx="1e-9" ixy="0.0" ixz="0.0" iyy="1e-9" iyz="0.0" izz="1e-9"/>
    </inertial>
    <visual>
      <origin xyz="0 0 0"/>
      <geometry>
        <sphere radius="0.015"/>
      </geometry>
    </visual>
    <collision>
      <origin xyz="0 0 0"/>
      <geometry>
        <sphere radius="0.015"/>
      </geometry>
    </collision>
  </link>
  <joint name="rear_right_foot_contact_joint" type="fixed">
    <origin xyz="0 0 -0.135"/>
    <parent link="rear_right_lower_leg_link"/>
    <child link="rear_right_foot_contact_link"/>
  </joint>
</robot>

