<?xml version="1.0"?>
<robot xmlns:xacro="http://www.ros.org/wiki/xacro">

<xacro:include filename="$(find ester_description)/urdf/constants.xacro"/>
<xacro:include filename="$(find ester_description)/urdf/leg/upper_leg.transmission.xacro"/>

<xacro:macro name="upper_leg"
             params="front_side *joint_origin **inertial **geometry">
    <link name="${front_side}_upper_leg_link">
        <inertial>
            <xacro:insert_block name="inertial"/>
        </inertial>
        <visual>
            <xacro:insert_block name="geometry"/>
        </visual>
        <collision>
            <xacro:insert_block name="geometry"/>
        </collision>
    </link>

    <joint name="${front_side}_upper_leg_joint" type="revolute">
        <xacro:insert_block name="joint_origin"/>
        <axis xyz="0 1 0"/>
	<limit upper="${3 * M_PI / 4}" lower="${-3 * M_PI / 4}" velocity="${MOTOR_VELOCITY_LIMIT / 16}" effort="${MOTOR_EFFORT_LIMIT * 16}"/>
        <dynamics damping="${JOINT_DAMPING}" friction="${JOINT_FRICTION}"/>
        <parent link="${front_side}_hip_fe_link"/>
        <child link="${front_side}_upper_leg_link"/>
    </joint>

    <xacro:upper_leg_transmission front_side="${front_side}"/>
</xacro:macro>

<xacro:macro name="front_left_upper_leg">
    <xacro:upper_leg front_side="front_left">
	    <origin xyz="0 0.01415 0" rpy="0 ${FRONT_LEG_PITCH} 0"/>
        <inertial>
            <mass value="0.158127"/>
            <origin xyz="0.0 0.022563 -0.07012" rpy="0 0 ${M_PI/2}"/>
            <inertia ixx="2.824E-04" ixy="4.259E-09" ixz="-6.584E-08"
                     iyy="2.882E-04" iyz="3.543E-05" izz="3.742E-05"/>
        </inertial>
        <geometry>
            <origin xyz="0 0 0" rpy="0 0 ${M_PI/2}"/>
            <geometry>
                <mesh filename="package://ester_description/meshes/leg/front_upper_leg.stl" scale="0.001 0.001 0.001"/>
            </geometry>
        </geometry>
    </xacro:upper_leg>
</xacro:macro>

<xacro:macro name="front_right_upper_leg">
    <xacro:upper_leg front_side="front_right">
	    <origin xyz="0 -0.01415 0" rpy="0 ${FRONT_LEG_PITCH} 0"/>
        <inertial>
            <mass value="0.158127"/>
            <origin xyz="0.0 -0.022563 -0.07012" rpy="0 0 ${-M_PI/2}"/>
            <inertia ixx="2.824E-04" ixy="4.259E-09" ixz="-6.584E-08"
                     iyy="2.882E-04" iyz="3.543E-05" izz="3.742E-05"/>
        </inertial>
        <geometry>
            <origin xyz="0 0 0" rpy="0 0 ${-M_PI/2}"/>
            <geometry>
                <mesh filename="package://ester_description/meshes/leg/front_upper_leg.stl" scale="0.001 0.001 0.001"/>
            </geometry>
        </geometry>
    </xacro:upper_leg>
</xacro:macro>

<xacro:macro name="rear_left_upper_leg">
    <xacro:upper_leg front_side="rear_left">
        <origin xyz="0 0.01415 0" rpy="0 0 0"/>
        <inertial>
            <mass value="0.160653"/>
            <origin xyz="0.0 0.02256 -0.07763" rpy="0 0 ${M_PI/2}"/>
            <inertia ixx="3.140E-04" ixy="6.009E-09" ixz="-7.395E-08"
                     iyy="3.203E-04" iyz="3.738E-05" izz="3.808E-05"/>
        </inertial>
        <geometry>
            <origin xyz="0 0 0" rpy="0 0 ${M_PI/2}"/>
            <geometry>
                <mesh filename="package://ester_description/meshes/leg/rear_upper_leg.stl" scale="0.001 0.001 0.001"/>
            </geometry>
        </geometry>
    </xacro:upper_leg>
</xacro:macro>

<xacro:macro name="rear_right_upper_leg">
    <xacro:upper_leg front_side="rear_right">
        <origin xyz="0 -0.01415 0" rpy="0 0 0"/>
        <inertial>
            <mass value="0.160653"/>
            <origin xyz="0.0 -0.02256 -0.07763" rpy="0 0 ${-M_PI/2}"/>
            <inertia ixx="3.140E-04" ixy="6.009E-09" ixz="-7.395E-08"
                     iyy="3.203E-04" iyz="3.738E-05" izz="3.808E-05"/>
        </inertial>
        <geometry>
            <origin xyz="0 0 0" rpy="0 0 ${-M_PI/2}"/>
            <geometry>
                <mesh filename="package://ester_description/meshes/leg/rear_upper_leg.stl" scale="0.001 0.001 0.001"/>
            </geometry>
        </geometry>
    </xacro:upper_leg>
</xacro:macro>

</robot>
