<?xml version="1.0"?>
<robot xmlns:xacro="http://www.ros.org/wiki/xacro">

<xacro:include filename="$(find ester_description)/urdf/spine/spine_yaw.transmission.xacro"/>

<xacro:macro name="spine_yaw"
             params="front *joint_origin **inertial **geometry">
    <link name="${front}_spine_yaw_link">
        <inertial>
            <xacro:insert_block name="inertial"/>
        </inertial>
        <visual>
            <xacro:insert_block name="geometry"/>
        </visual>
        <collision>
            <xacro:insert_block name="geometry"/>
        </collision>
    </link>

    <joint name="${front}_spine_yaw_joint" type="revolute">
        <xacro:insert_block name="joint_origin"/>
        <axis xyz="0 0 1"/>
        <limit upper="${M_PI / 12}" lower="${-M_PI / 12}" velocity="${MOTOR_VELOCITY_LIMIT / 9}" effort="${MOTOR_EFFORT_LIMIT * 9}"/>
        <dynamics damping="${JOINT_DAMPING}" friction="${JOINT_FRICTION}"/>
        <parent link="${front}_spine_pitch_link"/>
        <child link="${front}_spine_yaw_link"/>
    </joint>

    <xacro:spine_yaw_transmission front="${front}"/>
</xacro:macro>

<xacro:macro name="front_spine_yaw">
    <xacro:spine_yaw front="front">
        <origin xyz="0 0 0.02115" rpy="0 0 0"/>
        <inertial>
            <mass value="0.16423"/>
            <origin xyz="0.039502 0.000163 -0.078237"/>
            <inertia ixx="8.265E-3" ixy="-3.108E-5" ixz="-7.159E-4"
                     iyy="6.946E-3" iyz="6.255E-5" izz="3.327E-3"/>
        </inertial>
        <geometry>
            <origin xyz="0 0 0"/>
            <geometry>
                <mesh filename="package://ester_description/meshes/spine/front_spine_yaw.stl" scale="0.001 0.001 0.001"/>
            </geometry>
        </geometry>
    </xacro:spine_yaw>
</xacro:macro>

<xacro:macro name="rear_spine_yaw">
    <xacro:spine_yaw front="rear">
        <origin xyz="0 0 0.02115" rpy="0 0 0"/>
        <inertial>
            <mass value="1.384897"/>
            <origin xyz="-0.094734 -0.002584 -0.044113"/>
            <inertia ixx="3.585E-2" ixy="8.222E-4" ixz="-2.140E-3"
                     iyy="6.227E-2" iyz="2.131E-3" izz="4.841E-2"/>
        </inertial>
        <geometry>
            <origin xyz="0 0 0"/>
            <geometry>
                <mesh filename="package://ester_description/meshes/spine/rear_spine_yaw.stl" scale="0.001 0.001 0.001"/>
            </geometry>
        </geometry>
    </xacro:spine_yaw>
</xacro:macro>

</robot>
