<?xml version="1.0" ?>
<!-- =================================================================================== -->
<!-- |    This document was autogenerated by xacro from ester_description/urdf/ester.urdf.xacro | -->
<!-- |    EDITING THIS FILE BY HAND IS NOT RECOMMENDED                                 | -->
<!-- =================================================================================== -->
<robot name="ester">
  <gazebo>
    <plugin filename="libester_hwi_plugin.so" name="ester_hwi_plugin"/>
    <selfCollide>false</selfCollide>
  </gazebo>
  <!-- Dummy parent link for Gazebo -->
  <link name="base_link"/>
  <link name="spine_center_link">
    <inertial>
      <mass value="0.412971"/>
      <origin xyz="-0.000375 -0.001924 -0.03454"/>
      <inertia ixx="9.067E-3" ixy="-8.901E-4" ixz="7.674E-5" iyy="5.927E-3" iyz="4.114E-5" izz="1.033E-2"/>
    </inertial>
    <visual>
      <origin rpy="0 0 0" xyz="0 0 0"/>
      <geometry>
        <mesh filename="/home/nick/catkin_ws/src/ESTER/ester_description/meshes/spine/spine_center.stl" scale="0.001 0.001 0.001"/>
      </geometry>
    </visual>
    <collision>
      <origin rpy="0 0 0" xyz="0 0 0"/>
      <geometry>
        <mesh filename="/home/nick/catkin_ws/src/ESTER/ester_description/meshes/spine/spine_center.stl" scale="0.001 0.001 0.001"/>
      </geometry>
    </collision>
  </link>
  <joint name="spine_center_joint" type="fixed">
    <origin rpy="0 0 0" xyz="0 0 0"/>
    <parent link="base_link"/>
    <child link="spine_center_link"/>
  </joint>
  <link name="front_spine_pitch_link">
    <inertial>
      <mass value="0.135102"/>
      <origin xyz="-0.007075 -0.000188 -0.006485"/>
      <inertia ixx="5.528E-4" ixy="3.264E-6" ixz="8.008E-5" iyy="8.590E-4" iyz="2.381E-6" izz="6.630E-4"/>
    </inertial>
    <visual>
      <origin xyz="0 0 0"/>
      <geometry>
        <mesh filename="/home/nick/catkin_ws/src/ESTER/ester_description/meshes/spine/front_spine_pitch.stl" scale="0.001 0.001 0.001"/>
      </geometry>
    </visual>
    <collision>
      <origin xyz="0 0 0"/>
      <geometry>
        <mesh filename="/home/nick/catkin_ws/src/ESTER/ester_description/meshes/spine/front_spine_pitch.stl" scale="0.001 0.001 0.001"/>
      </geometry>
    </collision>
  </link>
  <joint name="front_spine_pitch_joint" type="revolute">
    <origin rpy="0 0 0" xyz="0.045 0.0 -0.015"/>
    <axis xyz="0 1 0"/>
    <limit effort="4.32" lower="-0.2617993877991494" upper="0.2617993877991494" velocity="46.875"/>
    <dynamics damping="0.001" friction="0.0"/>
    <parent link="spine_center_link"/>
    <child link="front_spine_pitch_link"/>
  </joint>
  <transmission name="front_spine_pitch_transmission">
    <type>transmission_interface/SimpleTransmission</type>
    <joint name="front_spine_pitch_joint">
      <hardwareInterface>hardware_interface/EffortJointInterface</hardwareInterface>
    </joint>
    <actuator name="front_spine_pitch_motor">
      <hardwareInterface>hardware_interface/EffortJointInterface</hardwareInterface>
      <mechanicalReduction>1</mechanicalReduction>
    </actuator>
  </transmission>
  <link name="rear_spine_pitch_link">
    <inertial>
      <mass value="0.131658"/>
      <origin xyz="-0.006128 0.00016 -0.007237"/>
      <inertia ixx="5.096E-4" ixy="-3.566E-6" ixz="4.115E-5" iyy="7.796E-4" iyz="-2.003E-6" izz="6.027E-4"/>
    </inertial>
    <visual>
      <origin xyz="0 0 0"/>
      <geometry>
        <mesh filename="/home/nick/catkin_ws/src/ESTER/ester_description/meshes/spine/rear_spine_pitch.stl" scale="0.001 0.001 0.001"/>
      </geometry>
    </visual>
    <collision>
      <origin xyz="0 0 0"/>
      <geometry>
        <mesh filename="/home/nick/catkin_ws/src/ESTER/ester_description/meshes/spine/rear_spine_pitch.stl" scale="0.001 0.001 0.001"/>
      </geometry>
    </collision>
  </link>
  <joint name="rear_spine_pitch_joint" type="revolute">
    <origin rpy="0 0 0" xyz="-0.045 0.0 -0.015"/>
    <axis xyz="0 1 0"/>
    <limit effort="4.32" lower="-0.2617993877991494" upper="0.2617993877991494" velocity="46.875"/>
    <dynamics damping="0.001" friction="0.0"/>
    <parent link="spine_center_link"/>
    <child link="rear_spine_pitch_link"/>
  </joint>
  <transmission name="rear_spine_pitch_transmission">
    <type>transmission_interface/SimpleTransmission</type>
    <joint name="rear_spine_pitch_joint">
      <hardwareInterface>hardware_interface/EffortJointInterface</hardwareInterface>
    </joint>
    <actuator name="rear_spine_pitch_motor">
      <hardwareInterface>hardware_interface/EffortJointInterface</hardwareInterface>
      <mechanicalReduction>1</mechanicalReduction>
    </actuator>
  </transmission>
  <link name="front_spine_yaw_link">
    <inertial>
      <mass value="0.16423"/>
      <origin xyz="0.039502 0.000163 -0.078237"/>
      <inertia ixx="8.265E-3" ixy="-3.108E-5" ixz="-7.159E-4" iyy="6.946E-3" iyz="6.255E-5" izz="3.327E-3"/>
    </inertial>
    <visual>
      <origin xyz="0 0 0"/>
      <geometry>
        <mesh filename="/home/nick/catkin_ws/src/ESTER/ester_description/meshes/spine/front_spine_yaw.stl" scale="0.001 0.001 0.001"/>
      </geometry>
    </visual>
    <collision>
      <origin xyz="0 0 0"/>
      <geometry>
        <mesh filename="/home/nick/catkin_ws/src/ESTER/ester_description/meshes/spine/front_spine_yaw.stl" scale="0.001 0.001 0.001"/>
      </geometry>
    </collision>
  </link>
  <joint name="front_spine_yaw_joint" type="revolute">
    <origin rpy="0 0 0" xyz="0 0 0.02115"/>
    <axis xyz="0 0 1"/>
    <limit effort="2.43" lower="-0.2617993877991494" upper="0.2617993877991494" velocity="83.33333333333333"/>
    <dynamics damping="0.001" friction="0.0"/>
    <parent link="front_spine_pitch_link"/>
    <child link="front_spine_yaw_link"/>
  </joint>
  <transmission name="front_spine_yaw_transmission">
    <type>transmission_interface/SimpleTransmission</type>
    <joint name="front_spine_yaw_joint">
      <hardwareInterface>hardware_interface/EffortJointInterface</hardwareInterface>
    </joint>
    <actuator name="front_spine_yaw_motor">
      <hardwareInterface>hardware_interface/EffortJointInterface</hardwareInterface>
      <mechanicalReduction>1</mechanicalReduction>
    </actuator>
  </transmission>
  <link name="rear_spine_yaw_link">
    <inertial>
      <mass value="1.384897"/>
      <origin xyz="-0.094734 -0.002584 -0.044113"/>
      <inertia ixx="3.585E-2" ixy="8.222E-4" ixz="-2.140E-3" iyy="6.227E-2" iyz="2.131E-3" izz="4.841E-2"/>
    </inertial>
    <visual>
      <origin xyz="0 0 0"/>
      <geometry>
        <mesh filename="/home/nick/catkin_ws/src/ESTER/ester_description/meshes/spine/rear_spine_yaw.stl" scale="0.001 0.001 0.001"/>
      </geometry>
    </visual>
    <collision>
      <origin xyz="0 0 0"/>
      <geometry>
        <mesh filename="/home/nick/catkin_ws/src/ESTER/ester_description/meshes/spine/rear_spine_yaw.stl" scale="0.001 0.001 0.001"/>
      </geometry>
    </collision>
  </link>
  <joint name="rear_spine_yaw_joint" type="revolute">
    <origin rpy="0 0 0" xyz="0 0 0.02115"/>
    <axis xyz="0 0 1"/>
    <limit effort="2.43" lower="-0.2617993877991494" upper="0.2617993877991494" velocity="83.33333333333333"/>
    <dynamics damping="0.001" friction="0.0"/>
    <parent link="rear_spine_pitch_link"/>
    <child link="rear_spine_yaw_link"/>
  </joint>
  <transmission name="rear_spine_yaw_transmission">
    <type>transmission_interface/SimpleTransmission</type>
    <joint name="rear_spine_yaw_joint">
      <hardwareInterface>hardware_interface/EffortJointInterface</hardwareInterface>
    </joint>
    <actuator name="rear_spine_yaw_motor">
      <hardwareInterface>hardware_interface/EffortJointInterface</hardwareInterface>
      <mechanicalReduction>1</mechanicalReduction>
    </actuator>
  </transmission>
  <link name="imu_link">
    <origin rpy="0 0 0" xyz="0 0 0"/>
    <inertial>
      <mass value="1e-9"/>
      <origin rpy="0 0 0" xyz="0 0 0"/>
      <inertia ixx="1e-9" ixy="0" ixz="0" iyy="1e-9" iyz="0" izz="1e-9"/>
    </inertial>
  </link>
  <joint name="imu_joint" type="fixed">
    <origin rpy="0 0 0" xyz="-0.13275 0 0.017"/>
    <parent link="rear_spine_yaw_link"/>
    <child link="imu_link"/>
  </joint>
  <gazebo>
    <plugin filename="libgazebo_ros_imu.so" name="imu_plugin">
      <alwaysOn>true</alwaysOn>
      <bodyName>imu_link</bodyName>
      <frameName>imu_link</frameName>
      <topicName>/ester/imu/raw</topicName>
      <serviceName>/ester/imu_service</serviceName>
      <gaussianNoise>0.01</gaussianNoise>
      <updateRate>20.0</updateRate>
    </plugin>
  </gazebo>
  <link name="front_left_hip_aa_link">
    <inertial>
      <mass value="0.149885"/>
      <origin rpy="0 0 3.141592653589793" xyz="-0.017329 -0.026389 0.014"/>
      <inertia ixx="2.575E-04" ixy="2.519E-05" ixz="7.023E-09" iyy="2.683E-05" iyz="-6.917E-08" izz="2.557E-04"/>
    </inertial>
    <visual>
      <origin rpy="0 0 3.141592653589793" xyz="0 0 0"/>
      <geometry>
        <mesh filename="/home/nick/catkin_ws/src/ESTER/ester_description/meshes/leg/front_hip_aa.stl" scale="0.001 0.001 0.001"/>
      </geometry>
    </visual>
    <collision>
      <origin rpy="0 0 3.141592653589793" xyz="0 0 0"/>
      <geometry>
        <mesh filename="/home/nick/catkin_ws/src/ESTER/ester_description/meshes/leg/front_hip_aa.stl" scale="0.001 0.001 0.001"/>
      </geometry>
    </collision>
  </link>
  <joint name="front_left_hip_aa_joint" type="fixed">
    <origin rpy="0 -0.7853981633974483 0" xyz="0.01 -0.024 -0.1065"/>
    <parent link="front_spine_yaw_link"/>
    <child link="front_left_hip_aa_link"/>
  </joint>
  <link name="front_left_hip_fe_link">
    <inertial>
      <mass value="0.139328"/>
      <origin rpy="0 0 3.141592653589793" xyz="0.01808 0.004477 -0.014405"/>
      <inertia ixx="6.080E-05" ixy="-3.521E-06" ixz="2.540E-06" iyy="1.052E-04" iyz="1.247E-05" izz="7.157E-05"/>
    </inertial>
    <visual>
      <origin rpy="0 0 3.141592653589793" xyz="0 0 -0.003"/>
      <geometry>
        <mesh filename="/home/nick/catkin_ws/src/ESTER/ester_description/meshes/leg/front_hip_fe.stl" scale="0.001 0.001 0.001"/>
      </geometry>
    </visual>
    <collision>
      <origin rpy="0 0 3.141592653589793" xyz="0 0 -0.003"/>
      <geometry>
        <mesh filename="/home/nick/catkin_ws/src/ESTER/ester_description/meshes/leg/front_hip_fe.stl" scale="0.001 0.001 0.001"/>
      </geometry>
    </collision>
  </link>
  <joint name="front_left_hip_fe_joint" type="revolute">
    <origin rpy="0 0 0" xyz="0.083972 0.0878 0"/>
    <axis xyz="1 0 0"/>
    <limit effort="2.43" lower="-0.17453292519943295" upper="0.7853981633974483" velocity="83.33333333333333"/>
    <dynamics damping="0.001" friction="0.0"/>
    <parent link="front_left_hip_aa_link"/>
    <child link="front_left_hip_fe_link"/>
  </joint>
  <transmission name="front_left_hip_fe_transmission">
    <type>transmission_interface/SimpleTransmission</type>
    <joint name="front_left_hip_fe_joint">
      <hardwareInterface>hardware_interface/EffortJointInterface</hardwareInterface>
    </joint>
    <actuator name="front_left_hip_fe_motor">
      <hardwareInterface>hardware_interface/EffortJointInterface</hardwareInterface>
      <mechanicalReduction>1</mechanicalReduction>
    </actuator>
  </transmission>
  <link name="front_left_upper_leg_link">
    <inertial>
      <mass value="0.158127"/>
      <origin rpy="0 0 1.5707963267948966" xyz="0.0 0.022563 -0.07012"/>
      <inertia ixx="2.824E-04" ixy="4.259E-09" ixz="-6.584E-08" iyy="2.882E-04" iyz="3.543E-05" izz="3.742E-05"/>
    </inertial>
    <visual>
      <origin rpy="0 0 1.5707963267948966" xyz="0 0 0"/>
      <geometry>
        <mesh filename="/home/nick/catkin_ws/src/ESTER/ester_description/meshes/leg/front_upper_leg.stl" scale="0.001 0.001 0.001"/>
      </geometry>
    </visual>
    <collision>
      <origin rpy="0 0 1.5707963267948966" xyz="0 0 0"/>
      <geometry>
        <mesh filename="/home/nick/catkin_ws/src/ESTER/ester_description/meshes/leg/front_upper_leg.stl" scale="0.001 0.001 0.001"/>
      </geometry>
    </collision>
  </link>
  <joint name="front_left_upper_leg_joint" type="revolute">
    <origin rpy="0 0.7853981633974483 0" xyz="0 0.01415 0"/>
    <axis xyz="0 1 0"/>
    <limit effort="4.32" lower="-2.356194490192345" upper="2.356194490192345" velocity="46.875"/>
    <dynamics damping="0.001" friction="0.0"/>
    <parent link="front_left_hip_fe_link"/>
    <child link="front_left_upper_leg_link"/>
  </joint>
  <transmission name="front_left_upper_leg_transmission">
    <type>transmission_interface/SimpleTransmission</type>
    <joint name="front_left_upper_leg_joint">
      <hardwareInterface>hardware_interface/EffortJointInterface</hardwareInterface>
    </joint>
    <actuator name="front_left_upper_leg_motor">
      <hardwareInterface>hardware_interface/EffortJointInterface</hardwareInterface>
      <mechanicalReduction>1</mechanicalReduction>
    </actuator>
  </transmission>
  <link name="front_left_lower_leg_link">
    <inertial>
      <mass value="0.023961"/>
      <origin xyz="0 0.00816 -0.044589"/>
      <inertia ixx="3.727E-05" ixy="-5.628E-16" ixz="2.285E-15" iyy="3.709E-05" iyz="-5.027E-06" izz="1.815E-06"/>
    </inertial>
    <visual>
      <origin rpy="0 0 0" xyz="0 0 0"/>
      <geometry>
        <mesh filename="/home/nick/catkin_ws/src/ESTER/ester_description/meshes/leg/front_lower_leg.stl" scale="0.001 0.001 0.001"/>
      </geometry>
    </visual>
    <collision>
      <origin rpy="0 0 0" xyz="0 0 0"/>
      <geometry>
        <mesh filename="/home/nick/catkin_ws/src/ESTER/ester_description/meshes/leg/front_lower_leg.stl" scale="0.001 0.001 0.001"/>
      </geometry>
    </collision>
  </link>
  <joint name="front_left_lower_leg_joint" type="revolute">
    <axis xyz="0 1 0"/>
    <limit effort="4.32" lower="-2.5132741228718345" upper="2.5132741228718345" velocity="46.875"/>
    <dynamics damping="0.001" friction="0.0"/>
    <origin rpy="0 0 0" xyz="0 0.0315 -0.1232"/>
    <parent link="front_left_upper_leg_link"/>
    <child link="front_left_lower_leg_link"/>
  </joint>
  <transmission name="front_left_lower_leg_transmission">
    <type>transmission_interface/SimpleTransmission</type>
    <joint name="front_left_lower_leg_joint">
      <hardwareInterface>hardware_interface/EffortJointInterface</hardwareInterface>
    </joint>
    <actuator name="front_left_lower_leg_motor">
      <hardwareInterface>hardware_interface/EffortJointInterface</hardwareInterface>
      <mechanicalReduction>1</mechanicalReduction>
    </actuator>
  </transmission>
  <link name="front_left_foot_contact_link">
    <inertial>
      <mass value="0.01"/>
      <origin xyz="0 0 0"/>
      <inertia ixx="1e-9" ixy="0.0" ixz="0.0" iyy="1e-9" iyz="0.0" izz="1e-9"/>
    </inertial>
    <visual>
      <origin xyz="0 0 0"/>
      <geometry>
        <sphere radius="0.015"/>
      </geometry>
    </visual>
    <collision>
      <origin xyz="0 0 0"/>
      <geometry>
        <sphere radius="0.015"/>
      </geometry>
    </collision>
  </link>
  <joint name="front_left_foot_contact_joint" type="fixed">
    <origin xyz="0 0 -0.105"/>
    <parent link="front_left_lower_leg_link"/>
    <child link="front_left_foot_contact_link"/>
  </joint>
  <gazebo reference="front_left_foot_contact_link">
    <sensor name="front_left_contact_sensor" type="contact">
      <plugin filename="libester_contact.so" name="front_left_contact_plugin">
        <topic>/ester/front_left_foot_contact</topic>
        <frame>front_left_upper_leg_link</frame>
      </plugin>
      <contact>
        <collision>front_left_lower_leg_link_fixed_joint_lump__front_left_foot_contact_link_collision_1</collision>
        <update_rate>100</update_rate>
      </contact>
    </sensor>
  </gazebo>
  <link name="front_right_hip_aa_link">
    <inertial>
      <mass value="0.149885"/>
      <origin xyz="-0.017329 -0.026389 0.014"/>
      <inertia ixx="2.575E-04" ixy="2.519E-05" ixz="7.023E-09" iyy="2.683E-05" iyz="-6.917E-08" izz="2.557E-04"/>
    </inertial>
    <visual>
      <origin rpy="0 0 0" xyz="0 0 0"/>
      <geometry>
        <mesh filename="/home/nick/catkin_ws/src/ESTER/ester_description/meshes/leg/front_hip_aa.stl" scale="0.001 0.001 0.001"/>
      </geometry>
    </visual>
    <collision>
      <origin rpy="0 0 0" xyz="0 0 0"/>
      <geometry>
        <mesh filename="/home/nick/catkin_ws/src/ESTER/ester_description/meshes/leg/front_hip_aa.stl" scale="0.001 0.001 0.001"/>
      </geometry>
    </collision>
  </link>
  <joint name="front_right_hip_aa_joint" type="fixed">
    <origin rpy="0 -0.7853981633974483 0" xyz="0.01 0.024 -0.1065"/>
    <parent link="front_spine_yaw_link"/>
    <child link="front_right_hip_aa_link"/>
  </joint>
  <link name="front_right_hip_fe_link">
    <inertial>
      <mass value="0.153185"/>
      <origin rpy="0 0 3.141592653589793" xyz="0.01808 0.004477 -0.011405"/>
      <inertia ixx="6.080E-05" ixy="3.521E-06" ixz="2.540E-06" iyy="1.052E-04" iyz="-1.247E-05" izz="7.157E-05"/>
    </inertial>
    <visual>
      <origin rpy="0 0 3.141592653589793" xyz="0 0 0"/>
      <geometry>
        <mesh filename="/home/nick/catkin_ws/src/ESTER/ester_description/meshes/leg/front_hip_fe.stl" scale="0.001 -0.001 0.001"/>
      </geometry>
    </visual>
    <collision>
      <origin rpy="0 0 3.141592653589793" xyz="0 0 0"/>
      <geometry>
        <mesh filename="/home/nick/catkin_ws/src/ESTER/ester_description/meshes/leg/front_hip_fe.stl" scale="0.001 -0.001 0.001"/>
      </geometry>
    </collision>
  </link>
  <joint name="front_right_hip_fe_joint" type="revolute">
    <origin rpy="0 0 0" xyz="0.083972 -0.0878 0"/>
    <axis xyz="1 0 0"/>
    <limit effort="2.43" lower="-0.7853981633974483" upper="0.17453292519943295" velocity="83.33333333333333"/>
    <dynamics damping="0.001" friction="0.0"/>
    <parent link="front_right_hip_aa_link"/>
    <child link="front_right_hip_fe_link"/>
  </joint>
  <transmission name="front_right_hip_fe_transmission">
    <type>transmission_interface/SimpleTransmission</type>
    <joint name="front_right_hip_fe_joint">
      <hardwareInterface>hardware_interface/EffortJointInterface</hardwareInterface>
    </joint>
    <actuator name="front_right_hip_fe_motor">
      <hardwareInterface>hardware_interface/EffortJointInterface</hardwareInterface>
      <mechanicalReduction>1</mechanicalReduction>
    </actuator>
  </transmission>
  <link name="front_right_upper_leg_link">
    <inertial>
      <mass value="0.158127"/>
      <origin rpy="0 0 -1.5707963267948966" xyz="0.0 -0.022563 -0.07012"/>
      <inertia ixx="2.824E-04" ixy="4.259E-09" ixz="-6.584E-08" iyy="2.882E-04" iyz="3.543E-05" izz="3.742E-05"/>
    </inertial>
    <visual>
      <origin rpy="0 0 -1.5707963267948966" xyz="0 0 0"/>
      <geometry>
        <mesh filename="/home/nick/catkin_ws/src/ESTER/ester_description/meshes/leg/front_upper_leg.stl" scale="0.001 0.001 0.001"/>
      </geometry>
    </visual>
    <collision>
      <origin rpy="0 0 -1.5707963267948966" xyz="0 0 0"/>
      <geometry>
        <mesh filename="/home/nick/catkin_ws/src/ESTER/ester_description/meshes/leg/front_upper_leg.stl" scale="0.001 0.001 0.001"/>
      </geometry>
    </collision>
  </link>
  <joint name="front_right_upper_leg_joint" type="revolute">
    <origin rpy="0 0.7853981633974483 0" xyz="0 -0.01415 0"/>
    <axis xyz="0 1 0"/>
    <limit effort="4.32" lower="-2.356194490192345" upper="2.356194490192345" velocity="46.875"/>
    <dynamics damping="0.001" friction="0.0"/>
    <parent link="front_right_hip_fe_link"/>
    <child link="front_right_upper_leg_link"/>
  </joint>
  <transmission name="front_right_upper_leg_transmission">
    <type>transmission_interface/SimpleTransmission</type>
    <joint name="front_right_upper_leg_joint">
      <hardwareInterface>hardware_interface/EffortJointInterface</hardwareInterface>
    </joint>
    <actuator name="front_right_upper_leg_motor">
      <hardwareInterface>hardware_interface/EffortJointInterface</hardwareInterface>
      <mechanicalReduction>1</mechanicalReduction>
    </actuator>
  </transmission>
  <link name="front_right_lower_leg_link">
    <inertial>
      <mass value="0.023961"/>
      <origin xyz="0 -0.00816 -0.044589"/>
      <inertia ixx="3.727E-05" ixy="-5.628E-16" ixz="2.285E-15" iyy="3.709E-05" iyz="5.027E-06" izz="1.815E-06"/>
    </inertial>
    <visual>
      <origin rpy="0 0 3.141592653589793" xyz="0 0 0"/>
      <geometry>
        <mesh filename="/home/nick/catkin_ws/src/ESTER/ester_description/meshes/leg/front_lower_leg.stl" scale="0.001 0.001 0.001"/>
      </geometry>
    </visual>
    <collision>
      <origin rpy="0 0 3.141592653589793" xyz="0 0 0"/>
      <geometry>
        <mesh filename="/home/nick/catkin_ws/src/ESTER/ester_description/meshes/leg/front_lower_leg.stl" scale="0.001 0.001 0.001"/>
      </geometry>
    </collision>
  </link>
  <joint name="front_right_lower_leg_joint" type="revolute">
    <axis xyz="0 1 0"/>
    <limit effort="4.32" lower="-2.5132741228718345" upper="2.5132741228718345" velocity="46.875"/>
    <dynamics damping="0.001" friction="0.0"/>
    <origin rpy="0 0 0" xyz="0 -0.0315 -0.1232"/>
    <parent link="front_right_upper_leg_link"/>
    <child link="front_right_lower_leg_link"/>
  </joint>
  <transmission name="front_right_lower_leg_transmission">
    <type>transmission_interface/SimpleTransmission</type>
    <joint name="front_right_lower_leg_joint">
      <hardwareInterface>hardware_interface/EffortJointInterface</hardwareInterface>
    </joint>
    <actuator name="front_right_lower_leg_motor">
      <hardwareInterface>hardware_interface/EffortJointInterface</hardwareInterface>
      <mechanicalReduction>1</mechanicalReduction>
    </actuator>
  </transmission>
  <link name="front_right_foot_contact_link">
    <inertial>
      <mass value="0.01"/>
      <origin xyz="0 0 0"/>
      <inertia ixx="1e-9" ixy="0.0" ixz="0.0" iyy="1e-9" iyz="0.0" izz="1e-9"/>
    </inertial>
    <visual>
      <origin xyz="0 0 0"/>
      <geometry>
        <sphere radius="0.015"/>
      </geometry>
    </visual>
    <collision>
      <origin xyz="0 0 0"/>
      <geometry>
        <sphere radius="0.015"/>
      </geometry>
    </collision>
  </link>
  <joint name="front_right_foot_contact_joint" type="fixed">
    <origin xyz="0 0 -0.105"/>
    <parent link="front_right_lower_leg_link"/>
    <child link="front_right_foot_contact_link"/>
  </joint>
  <gazebo reference="front_right_foot_contact_link">
    <sensor name="front_right_contact_sensor" type="contact">
      <plugin filename="libester_contact.so" name="front_right_contact_plugin">
        <topic>/ester/front_right_foot_contact</topic>
        <frame>front_right_upper_leg_link</frame>
      </plugin>
      <contact>
        <collision>front_right_lower_leg_link_fixed_joint_lump__front_right_foot_contact_link_collision_1</collision>
        <update_rate>100</update_rate>
      </contact>
    </sensor>
  </gazebo>
  <link name="rear_left_hip_aa_link">
    <inertial>
      <mass value="0.149885"/>
      <origin rpy="0 0 3.141592653589793" xyz="-0.017329 -0.026389 0.014"/>
      <inertia ixx="2.575E-04" ixy="2.519E-05" ixz="7.023E-09" iyy="2.683E-05" iyz="-6.917E-08" izz="2.557E-04"/>
    </inertial>
    <visual>
      <origin rpy="0 0 3.141592653589793" xyz="0 0 0"/>
      <geometry>
        <mesh filename="/home/nick/catkin_ws/src/ESTER/ester_description/meshes/leg/front_hip_aa.stl" scale="0.001 0.001 0.001"/>
      </geometry>
    </visual>
    <collision>
      <origin rpy="0 0 3.141592653589793" xyz="0 0 0"/>
      <geometry>
        <mesh filename="/home/nick/catkin_ws/src/ESTER/ester_description/meshes/leg/front_hip_aa.stl" scale="0.001 0.001 0.001"/>
      </geometry>
    </collision>
  </link>
  <joint name="rear_left_hip_aa_joint" type="fixed">
    <origin rpy="0 0 0" xyz="-0.13424999999999998 -0.025 -0.02"/>
    <parent link="rear_spine_yaw_link"/>
    <child link="rear_left_hip_aa_link"/>
  </joint>
  <link name="rear_left_hip_fe_link">
    <inertial>
      <mass value="0.138767"/>
      <origin rpy="0 0 3.141592653589793" xyz="-0.01668 0.004473 -0.014463"/>
      <inertia ixx="6.067E-05" ixy="4.443E-06" ixz="-3.065E-06" iyy="1.026E-04" iyz="1.247E-05" izz="6.917E-05"/>
    </inertial>
    <visual>
      <origin rpy="0 0 3.141592653589793" xyz="0 0 -0.003"/>
      <geometry>
        <mesh filename="/home/nick/catkin_ws/src/ESTER/ester_description/meshes/leg/rear_hip_fe.stl" scale="-0.001 0.001 0.001"/>
      </geometry>
    </visual>
    <collision>
      <origin rpy="0 0 3.141592653589793" xyz="0 0 -0.003"/>
      <geometry>
        <mesh filename="/home/nick/catkin_ws/src/ESTER/ester_description/meshes/leg/rear_hip_fe.stl" scale="-0.001 0.001 0.001"/>
      </geometry>
    </collision>
  </link>
  <joint name="rear_left_hip_fe_joint" type="revolute">
    <origin rpy="0 0 0" xyz="0.054678 0.0878 0"/>
    <axis xyz="1 0 0"/>
    <limit effort="2.43" lower="-0.17453292519943295" upper="0.7853981633974483" velocity="83.33333333333333"/>
    <dynamics damping="0.001" friction="0.0"/>
    <parent link="rear_left_hip_aa_link"/>
    <child link="rear_left_hip_fe_link"/>
  </joint>
  <transmission name="rear_left_hip_fe_transmission">
    <type>transmission_interface/SimpleTransmission</type>
    <joint name="rear_left_hip_fe_joint">
      <hardwareInterface>hardware_interface/EffortJointInterface</hardwareInterface>
    </joint>
    <actuator name="rear_left_hip_fe_motor">
      <hardwareInterface>hardware_interface/EffortJointInterface</hardwareInterface>
      <mechanicalReduction>1</mechanicalReduction>
    </actuator>
  </transmission>
  <link name="rear_left_upper_leg_link">
    <inertial>
      <mass value="0.160653"/>
      <origin rpy="0 0 1.5707963267948966" xyz="0.0 0.02256 -0.07763"/>
      <inertia ixx="3.140E-04" ixy="6.009E-09" ixz="-7.395E-08" iyy="3.203E-04" iyz="3.738E-05" izz="3.808E-05"/>
    </inertial>
    <visual>
      <origin rpy="0 0 1.5707963267948966" xyz="0 0 0"/>
      <geometry>
        <mesh filename="/home/nick/catkin_ws/src/ESTER/ester_description/meshes/leg/rear_upper_leg.stl" scale="0.001 0.001 0.001"/>
      </geometry>
    </visual>
    <collision>
      <origin rpy="0 0 1.5707963267948966" xyz="0 0 0"/>
      <geometry>
        <mesh filename="/home/nick/catkin_ws/src/ESTER/ester_description/meshes/leg/rear_upper_leg.stl" scale="0.001 0.001 0.001"/>
      </geometry>
    </collision>
  </link>
  <joint name="rear_left_upper_leg_joint" type="revolute">
    <origin rpy="0 0 0" xyz="0 0.01415 0"/>
    <axis xyz="0 1 0"/>
    <limit effort="4.32" lower="-2.356194490192345" upper="2.356194490192345" velocity="46.875"/>
    <dynamics damping="0.001" friction="0.0"/>
    <parent link="rear_left_hip_fe_link"/>
    <child link="rear_left_upper_leg_link"/>
  </joint>
  <transmission name="rear_left_upper_leg_transmission">
    <type>transmission_interface/SimpleTransmission</type>
    <joint name="rear_left_upper_leg_joint">
      <hardwareInterface>hardware_interface/EffortJointInterface</hardwareInterface>
    </joint>
    <actuator name="rear_left_upper_leg_motor">
      <hardwareInterface>hardware_interface/EffortJointInterface</hardwareInterface>
      <mechanicalReduction>1</mechanicalReduction>
    </actuator>
  </transmission>
  <link name="rear_left_lower_leg_link">
    <inertial>
      <mass value="0.029071"/>
      <origin xyz="0 0.008801 -0.056722"/>
      <inertia ixx="6.791E-05" ixy="-1.480E-16" ixz="2.960E-15" iyy="6.774E-05" iyz="-7.319E-06" izz="2.092E-06"/>
    </inertial>
    <visual>
      <origin rpy="0 0 0" xyz="0 0 0"/>
      <geometry>
        <mesh filename="/home/nick/catkin_ws/src/ESTER/ester_description/meshes/leg/rear_lower_leg.stl" scale="0.001 0.001 0.001"/>
      </geometry>
    </visual>
    <collision>
      <origin rpy="0 0 0" xyz="0 0 0"/>
      <geometry>
        <mesh filename="/home/nick/catkin_ws/src/ESTER/ester_description/meshes/leg/rear_lower_leg.stl" scale="0.001 0.001 0.001"/>
      </geometry>
    </collision>
  </link>
  <joint name="rear_left_lower_leg_joint" type="revolute">
    <axis xyz="0 1 0"/>
    <limit effort="4.32" lower="-2.5132741228718345" upper="2.5132741228718345" velocity="46.875"/>
    <dynamics damping="0.001" friction="0.0"/>
    <origin rpy="0 0 0" xyz="0 0.0315 -0.134"/>
    <parent link="rear_left_upper_leg_link"/>
    <child link="rear_left_lower_leg_link"/>
  </joint>
  <transmission name="rear_left_lower_leg_transmission">
    <type>transmission_interface/SimpleTransmission</type>
    <joint name="rear_left_lower_leg_joint">
      <hardwareInterface>hardware_interface/EffortJointInterface</hardwareInterface>
    </joint>
    <actuator name="rear_left_lower_leg_motor">
      <hardwareInterface>hardware_interface/EffortJointInterface</hardwareInterface>
      <mechanicalReduction>1</mechanicalReduction>
    </actuator>
  </transmission>
  <link name="rear_left_foot_contact_link">
    <inertial>
      <mass value="0.01"/>
      <origin xyz="0 0 0"/>
      <inertia ixx="1e-9" ixy="0.0" ixz="0.0" iyy="1e-9" iyz="0.0" izz="1e-9"/>
    </inertial>
    <visual>
      <origin xyz="0 0 0"/>
      <geometry>
        <sphere radius="0.015"/>
      </geometry>
    </visual>
    <collision>
      <origin xyz="0 0 0"/>
      <geometry>
        <sphere radius="0.015"/>
      </geometry>
    </collision>
  </link>
  <joint name="rear_left_foot_contact_joint" type="fixed">
    <origin xyz="0 0 -0.135"/>
    <parent link="rear_left_lower_leg_link"/>
    <child link="rear_left_foot_contact_link"/>
  </joint>
  <gazebo reference="rear_left_foot_contact_link">
    <sensor name="rear_left_contact_sensor" type="contact">
      <plugin filename="libester_contact.so" name="rear_left_contact_plugin">
        <topic>/ester/rear_left_foot_contact</topic>
        <frame>rear_left_upper_leg_link</frame>
      </plugin>
      <contact>
        <collision>rear_left_lower_leg_link_fixed_joint_lump__rear_left_foot_contact_link_collision_1</collision>
        <update_rate>100</update_rate>
      </contact>
    </sensor>
  </gazebo>
  <link name="rear_right_hip_aa_link">
    <inertial>
      <mass value="0.149885"/>
      <origin xyz="-0.017329 -0.026389 0.014"/>
      <inertia ixx="2.575E-04" ixy="2.519E-05" ixz="7.023E-09" iyy="2.683E-05" iyz="-6.917E-08" izz="2.557E-04"/>
    </inertial>
    <visual>
      <origin rpy="0 0 0" xyz="0 0 0"/>
      <geometry>
        <mesh filename="/home/nick/catkin_ws/src/ESTER/ester_description/meshes/leg/front_hip_aa.stl" scale="0.001 0.001 0.001"/>
      </geometry>
    </visual>
    <collision>
      <origin rpy="0 0 0" xyz="0 0 0"/>
      <geometry>
        <mesh filename="/home/nick/catkin_ws/src/ESTER/ester_description/meshes/leg/front_hip_aa.stl" scale="0.001 0.001 0.001"/>
      </geometry>
    </collision>
  </link>
  <joint name="rear_right_hip_aa_joint" type="fixed">
    <origin rpy="0 0 0" xyz="-0.13424999999999998 0.025 -0.02"/>
    <parent link="rear_spine_yaw_link"/>
    <child link="rear_right_hip_aa_link"/>
  </joint>
  <link name="rear_right_hip_fe_link">
    <inertial>
      <mass value="0.138767"/>
      <origin rpy="0 0 0" xyz="0.01668 0.004473 -0.014463"/>
      <inertia ixx="6.067E-05" ixy="-4.443E-06" ixz="3.065E-06" iyy="1.026E-04" iyz="1.247E-05" izz="6.917E-05"/>
    </inertial>
    <visual>
      <origin rpy="0 0 0" xyz="0 0 -0.003"/>
      <geometry>
        <mesh filename="/home/nick/catkin_ws/src/ESTER/ester_description/meshes/leg/rear_hip_fe.stl" scale="0.001 0.001 0.001"/>
      </geometry>
    </visual>
    <collision>
      <origin rpy="0 0 0" xyz="0 0 -0.003"/>
      <geometry>
        <mesh filename="/home/nick/catkin_ws/src/ESTER/ester_description/meshes/leg/rear_hip_fe.stl" scale="0.001 0.001 0.001"/>
      </geometry>
    </collision>
  </link>
  <joint name="rear_right_hip_fe_joint" type="revolute">
    <origin rpy="0 0 0" xyz="0.054678 -0.0878 0"/>
    <axis xyz="1 0 0"/>
    <limit effort="2.43" lower="-0.7853981633974483" upper="0.17453292519943295" velocity="83.33333333333333"/>
    <dynamics damping="0.001" friction="0.0"/>
    <parent link="rear_right_hip_aa_link"/>
    <child link="rear_right_hip_fe_link"/>
  </joint>
  <transmission name="rear_right_hip_fe_transmission">
    <type>transmission_interface/SimpleTransmission</type>
    <joint name="rear_right_hip_fe_joint">
      <hardwareInterface>hardware_interface/EffortJointInterface</hardwareInterface>
    </joint>
    <actuator name="rear_right_hip_fe_motor">
      <hardwareInterface>hardware_interface/EffortJointInterface</hardwareInterface>
      <mechanicalReduction>1</mechanicalReduction>
    </actuator>
  </transmission>
  <link name="rear_right_upper_leg_link">
    <inertial>
      <mass value="0.160653"/>
      <origin rpy="0 0 -1.5707963267948966" xyz="0.0 -0.02256 -0.07763"/>
      <inertia ixx="3.140E-04" ixy="6.009E-09" ixz="-7.395E-08" iyy="3.203E-04" iyz="3.738E-05" izz="3.808E-05"/>
    </inertial>
    <visual>
      <origin rpy="0 0 -1.5707963267948966" xyz="0 0 0"/>
      <geometry>
        <mesh filename="/home/nick/catkin_ws/src/ESTER/ester_description/meshes/leg/rear_upper_leg.stl" scale="0.001 0.001 0.001"/>
      </geometry>
    </visual>
    <collision>
      <origin rpy="0 0 -1.5707963267948966" xyz="0 0 0"/>
      <geometry>
        <mesh filename="/home/nick/catkin_ws/src/ESTER/ester_description/meshes/leg/rear_upper_leg.stl" scale="0.001 0.001 0.001"/>
      </geometry>
    </collision>
  </link>
  <joint name="rear_right_upper_leg_joint" type="revolute">
    <origin rpy="0 0 0" xyz="0 -0.01415 0"/>
    <axis xyz="0 1 0"/>
    <limit effort="4.32" lower="-2.356194490192345" upper="2.356194490192345" velocity="46.875"/>
    <dynamics damping="0.001" friction="0.0"/>
    <parent link="rear_right_hip_fe_link"/>
    <child link="rear_right_upper_leg_link"/>
  </joint>
  <transmission name="rear_right_upper_leg_transmission">
    <type>transmission_interface/SimpleTransmission</type>
    <joint name="rear_right_upper_leg_joint">
      <hardwareInterface>hardware_interface/EffortJointInterface</hardwareInterface>
    </joint>
    <actuator name="rear_right_upper_leg_motor">
      <hardwareInterface>hardware_interface/EffortJointInterface</hardwareInterface>
      <mechanicalReduction>1</mechanicalReduction>
    </actuator>
  </transmission>
  <link name="rear_right_lower_leg_link">
    <inertial>
      <mass value="0.029071"/>
      <origin xyz="0 -0.008801 -0.056722"/>
      <inertia ixx="6.791E-05" ixy="-1.480E-16" ixz="2.960E-15" iyy="6.774E-05" iyz="7.319E-06" izz="2.092E-06"/>
    </inertial>
    <visual>
      <origin rpy="0 0 3.141592653589793" xyz="0 0 0"/>
      <geometry>
        <mesh filename="/home/nick/catkin_ws/src/ESTER/ester_description/meshes/leg/rear_lower_leg.stl" scale="0.001 0.001 0.001"/>
      </geometry>
    </visual>
    <collision>
      <origin rpy="0 0 3.141592653589793" xyz="0 0 0"/>
      <geometry>
        <mesh filename="/home/nick/catkin_ws/src/ESTER/ester_description/meshes/leg/rear_lower_leg.stl" scale="0.001 0.001 0.001"/>
      </geometry>
    </collision>
  </link>
  <joint name="rear_right_lower_leg_joint" type="revolute">
    <axis xyz="0 1 0"/>
    <limit effort="4.32" lower="-2.5132741228718345" upper="2.5132741228718345" velocity="46.875"/>
    <dynamics damping="0.001" friction="0.0"/>
    <origin rpy="0 0 0" xyz="0 -0.0315 -0.134"/>
    <parent link="rear_right_upper_leg_link"/>
    <child link="rear_right_lower_leg_link"/>
  </joint>
  <transmission name="rear_right_lower_leg_transmission">
    <type>transmission_interface/SimpleTransmission</type>
    <joint name="rear_right_lower_leg_joint">
      <hardwareInterface>hardware_interface/EffortJointInterface</hardwareInterface>
    </joint>
    <actuator name="rear_right_lower_leg_motor">
      <hardwareInterface>hardware_interface/EffortJointInterface</hardwareInterface>
      <mechanicalReduction>1</mechanicalReduction>
    </actuator>
  </transmission>
  <link name="rear_right_foot_contact_link">
    <inertial>
      <mass value="0.01"/>
      <origin xyz="0 0 0"/>
      <inertia ixx="1e-9" ixy="0.0" ixz="0.0" iyy="1e-9" iyz="0.0" izz="1e-9"/>
    </inertial>
    <visual>
      <origin xyz="0 0 0"/>
      <geometry>
        <sphere radius="0.015"/>
      </geometry>
    </visual>
    <collision>
      <origin xyz="0 0 0"/>
      <geometry>
        <sphere radius="0.015"/>
      </geometry>
    </collision>
  </link>
  <joint name="rear_right_foot_contact_joint" type="fixed">
    <origin xyz="0 0 -0.135"/>
    <parent link="rear_right_lower_leg_link"/>
    <child link="rear_right_foot_contact_link"/>
  </joint>
  <gazebo reference="rear_right_foot_contact_link">
    <sensor name="rear_right_contact_sensor" type="contact">
      <plugin filename="libester_contact.so" name="rear_right_contact_plugin">
        <topic>/ester/rear_right_foot_contact</topic>
        <frame>rear_right_upper_leg_link</frame>
      </plugin>
      <contact>
        <collision>rear_right_lower_leg_link_fixed_joint_lump__rear_right_foot_contact_link_collision_1</collision>
        <update_rate>100</update_rate>
      </contact>
    </sensor>
  </gazebo>
  <link name="head_link">
    <inertial>
      <mass value="0.000117815"/>
      <origin xyz="0.023956 -0.002 32.368"/>
      <inertia ixx="1.923E-08" ixy="1.698E-10" ixz="-7.927E-09" iyy="2.271E-08" iyz="-6.482E-11" izz="2.471E-08"/>
    </inertial>
    <visual>
      <origin rpy="0 0 0" xyz="0 0 0"/>
      <geometry>
        <mesh filename="/home/nick/catkin_ws/src/ESTER/ester_description/meshes/head/skull.stl" scale="0.001 0.001 0.001"/>
      </geometry>
    </visual>
    <collision>
      <origin rpy="0 0 0" xyz="0 0 0"/>
      <geometry>
        <mesh filename="/home/nick/catkin_ws/src/ESTER/ester_description/meshes/head/skull.stl" scale="0.001 0.001 0.001"/>
      </geometry>
    </collision>
  </link>
  <joint name="head_joint" type="fixed">
    <origin rpy="0 0.17453292519943295 0" xyz="0.11 0 0.02"/>
    <parent link="spine_center_link"/>
    <child link="head_link"/>
  </joint>
  <gazebo reference="head_joint">
    <preserveFixedJoint>true</preserveFixedJoint>
  </gazebo>
</robot>

